Workbook

Sheet Data
A1: date | B1: description | C1: price | D1: quantity | E1: total | F1: category | G1: product | H1: year | I1: month | J1: profit
A2: 45292 | B2: amortization | C2: NA | D2: NA | E2: 50 | F2: =IFERROR(LEFT(B2,FIND(":",B2)-1),B2) -> amortization | G2: NA | H2: =YEAR(A2) -> 2024 | I2: =MONTH(A2) -> 1 | J2: =IF(F2="net sales",E2, IF(F2="cogs",-E2, IF(OR(F2="marketing",F2="overhead",F2="payroll",F2="interest","amortization"),-E2,0))) -> 0
A3: 45292 | B3: cogs:product 1 | C3: 5.99 | D3: 71 | E3: 425.29 | F3: =IFERROR(LEFT(B3,FIND(":",B3)-1),B3) -> cogs | G3: =IFERROR(RIGHT(B3,LEN(B3)-FIND(":",B3)),"") -> product 1 | H3: =YEAR(A3) -> 2024 | I3: =MONTH(A3) -> 1 | J3: =IF(F3="net sales",E3, IF(F3="cogs",-E3, IF(OR(F3="marketing",F3="overhead",F3="payroll",F3="interest","amortization"),-E3,0))) -> -425.29
A4: 45292 | B4: cogs:product 2 | C4: 16.99 | D4: 3 | E4: 50.97 | F4: =IFERROR(LEFT(B4,FIND(":",B4)-1),B4) -> cogs | G4: =IFERROR(RIGHT(B4,LEN(B4)-FIND(":",B4)),"") -> product 2 | H4: =YEAR(A4) -> 2024 | I4: =MONTH(A4) -> 1 | J4: =IF(F4="net sales",E4, IF(F4="cogs",-E4, IF(OR(F4="marketing",F4="overhead",F4="payroll",F4="interest","amortization"),-E4,0))) -> -50.97
A5: 45292 | B5: cogs:product 3 | C5: 8.49 | D5: 78 | E5: 662.22 | F5: =IFERROR(LEFT(B5,FIND(":",B5)-1),B5) -> cogs | G5: =IFERROR(RIGHT(B5,LEN(B5)-FIND(":",B5)),"") -> product 3 | H5: =YEAR(A5) -> 2024 | I5: =MONTH(A5) -> 1 | J5: =IF(F5="net sales",E5, IF(F5="cogs",-E5, IF(OR(F5="marketing",F5="overhead",F5="payroll",F5="interest","amortization"),-E5,0))) -> -662.22
A6: 45292 | B6: marketing | C6: NA | D6: NA | E6: 99.99 | F6: =IFERROR(LEFT(B6,FIND(":",B6)-1),B6) -> marketing | G6: NA | H6: =YEAR(A6) -> 2024 | I6: =MONTH(A6) -> 1 | J6: =IF(F6="net sales",E6, IF(F6="cogs",-E6, IF(OR(F6="marketing",F6="overhead",F6="payroll",F6="interest","amortization"),-E6,0))) -> -99.99
A7: 45292 | B7: net sales:product 1 | C7: 9.99 | D7: 71 | E7: 709.29 | F7: =IFERROR(LEFT(B7,FIND(":",B7)-1),B7) -> net sales | G7: =IFERROR(RIGHT(B7,LEN(B7)-FIND(":",B7)),"") -> product 1 | H7: =YEAR(A7) -> 2024 | I7: =MONTH(A7) -> 1 | J7: =IF(F7="net sales",E7, IF(F7="cogs",-E7, IF(OR(F7="marketing",F7="overhead",F7="payroll",F7="interest","amortization"),-E7,0))) -> 709.29
A8: 45292 | B8: net sales:product 2 | C8: 24.99 | D8: 3 | E8: 74.97 | F8: =IFERROR(LEFT(B8,FIND(":",B8)-1),B8) -> net sales | G8: =IFERROR(RIGHT(B8,LEN(B8)-FIND(":",B8)),"") -> product 2 | H8: =YEAR(A8) -> 2024 | I8: =MONTH(A8) -> 1 | J8: =IF(F8="net sales",E8, IF(F8="cogs",-E8, IF(OR(F8="marketing",F8="overhead",F8="payroll",F8="interest","amortization"),-E8,0))) -> 74.97
A9: 45292 | B9: net sales:product 3 | C9: 12.49 | D9: 78 | E9: 974.22 | F9: =IFERROR(LEFT(B9,FIND(":",B9)-1),B9) -> net sales | G9: =IFERROR(RIGHT(B9,LEN(B9)-FIND(":",B9)),"") -> product 3 | H9: =YEAR(A9) -> 2024 | I9: =MONTH(A9) -> 1 | J9: =IF(F9="net sales",E9, IF(F9="cogs",-E9, IF(OR(F9="marketing",F9="overhead",F9="payroll",F9="interest","amortization"),-E9,0))) -> 974.22
A10: 45292 | B10: overhead | C10: NA | D10: NA | E10: 2000 | F10: =IFERROR(LEFT(B10,FIND(":",B10)-1),B10) -> overhead | G10: NA | H10: =YEAR(A10) -> 2024 | I10: =MONTH(A10) -> 1 | J10: =IF(F10="net sales",E10, IF(F10="cogs",-E10, IF(OR(F10="marketing",F10="overhead",F10="payroll",F10="interest","amortization"),-E10,0))) -> -2000
A11: 45293 | B11: cogs:product 1 | C11: 5.99 | D11: 65 | E11: 389.35 | F11: =IFERROR(LEFT(B11,FIND(":",B11)-1),B11) -> cogs | G11: =IFERROR(RIGHT(B11,LEN(B11)-FIND(":",B11)),"") -> product 1 | H11: =YEAR(A11) -> 2024 | I11: =MONTH(A11) -> 1 | J11: =IF(F11="net sales",E11, IF(F11="cogs",-E11, IF(OR(F11="marketing",F11="overhead",F11="payroll",F11="interest","amortization"),-E11,0))) -> -389.35
A12: 45293 | B12: cogs:product 2 | C12: 16.99 | D12: 3 | E12: 50.97 | F12: =IFERROR(LEFT(B12,FIND(":",B12)-1),B12) -> cogs | G12: =IFERROR(RIGHT(B12,LEN(B12)-FIND(":",B12)),"") -> product 2 | H12: =YEAR(A12) -> 2024 | I12: =MONTH(A12) -> 1 | J12: =IF(F12="net sales",E12, IF(F12="cogs",-E12, IF(OR(F12="marketing",F12="overhead",F12="payroll",F12="interest","amortization"),-E12,0))) -> -50.97
A13: 45293 | B13: cogs:product 3 | C13: 8.49 | D13: 226 | E13: 1918.74 | F13: =IFERROR(LEFT(B13,FIND(":",B13)-1),B13) -> cogs | G13: =IFERROR(RIGHT(B13,LEN(B13)-FIND(":",B13)),"") -> product 3 | H13: =YEAR(A13) -> 2024 | I13: =MONTH(A13) -> 1 | J13: =IF(F13="net sales",E13, IF(F13="cogs",-E13, IF(OR(F13="marketing",F13="overhead",F13="payroll",F13="interest","amortization"),-E13,0))) -> -1918.74
A14: 45293 | B14: marketing | C14: NA | D14: NA | E14: 99.96 | F14: =IFERROR(LEFT(B14,FIND(":",B14)-1),B14) -> marketing | G14: NA | H14: =YEAR(A14) -> 2024 | I14: =MONTH(A14) -> 1 | J14: =IF(F14="net sales",E14, IF(F14="cogs",-E14, IF(OR(F14="marketing",F14="overhead",F14="payroll",F14="interest","amortization"),-E14,0))) -> -99.96
A15: 45293 | B15: net sales:product 1 | C15: 9.99 | D15: 65 | E15: 649.35 | F15: =IFERROR(LEFT(B15,FIND(":",B15)-1),B15) -> net sales | G15: =IFERROR(RIGHT(B15,LEN(B15)-FIND(":",B15)),"") -> product 1 | H15: =YEAR(A15) -> 2024 | I15: =MONTH(A15) -> 1 | J15: =IF(F15="net sales",E15, IF(F15="cogs",-E15, IF(OR(F15="marketing",F15="overhead",F15="payroll",F15="interest","amortization"),-E15,0))) -> 649.35
A16: 45293 | B16: net sales:product 2 | C16: 24.99 | D16: 3 | E16: 74.97 | F16: =IFERROR(LEFT(B16,FIND(":",B16)-1),B16) -> net sales | G16: =IFERROR(RIGHT(B16,LEN(B16)-FIND(":",B16)),"") -> product 2 | H16: =YEAR(A16) -> 2024 | I16: =MONTH(A16) -> 1 | J16: =IF(F16="net sales",E16, IF(F16="cogs",-E16, IF(OR(F16="marketing",F16="overhead",F16="payroll",F16="interest","amortization"),-E16,0))) -> 74.97
A17: 45293 | B17: net sales:product 3 | C17: 12.49 | D17: 226 | E17: 2822.74 | F17: =IFERROR(LEFT(B17,FIND(":",B17)-1),B17) -> net sales | G17: =IFERROR(RIGHT(B17,LEN(B17)-FIND(":",B17)),"") -> product 3 | H17: =YEAR(A17) -> 2024 | I17: =MONTH(A17) -> 1 | J17: =IF(F17="net sales",E17, IF(F17="cogs",-E17, IF(OR(F17="marketing",F17="overhead",F17="payroll",F17="interest","amortization"),-E17,0))) -> 2822.74
A18: 45294 | B18: cogs:product 1 | C18: 5.99 | D18: 37 | E18: 221.63 | F18: =IFERROR(LEFT(B18,FIND(":",B18)-1),B18) -> cogs | G18: =IFERROR(RIGHT(B18,LEN(B18)-FIND(":",B18)),"") -> product 1 | H18: =YEAR(A18) -> 2024 | I18: =MONTH(A18) -> 1 | J18: =IF(F18="net sales",E18, IF(F18="cogs",-E18, IF(OR(F18="marketing",F18="overhead",F18="payroll",F18="interest","amortization"),-E18,0))) -> -221.63
A19: 45294 | B19: cogs:product 2 | C19: 16.99 | D19: 9 | E19: 152.91 | F19: =IFERROR(LEFT(B19,FIND(":",B19)-1),B19) -> cogs | G19: =IFERROR(RIGHT(B19,LEN(B19)-FIND(":",B19)),"") -> product 2 | H19: =YEAR(A19) -> 2024 | I19: =MONTH(A19) -> 1 | J19: =IF(F19="net sales",E19, IF(F19="cogs",-E19, IF(OR(F19="marketing",F19="overhead",F19="payroll",F19="interest","amortization"),-E19,0))) -> -152.91
A20: 45294 | B20: cogs:product 3 | C20: 8.49 | D20: 222 | E20: 1884.78 | F20: =IFERROR(LEFT(B20,FIND(":",B20)-1),B20) -> cogs | G20: =IFERROR(RIGHT(B20,LEN(B20)-FIND(":",B20)),"") -> product 3 | H20: =YEAR(A20) -> 2024 | I20: =MONTH(A20) -> 1 | J20: =IF(F20="net sales",E20, IF(F20="cogs",-E20, IF(OR(F20="marketing",F20="overhead",F20="payroll",F20="interest","amortization"),-E20,0))) -> -1884.78
A21: 45294 | B21: marketing | C21: NA | D21: NA | E21: 99.91 | F21: =IFERROR(LEFT(B21,FIND(":",B21)-1),B21) -> marketing | G21: NA | H21: =YEAR(A21) -> 2024 | I21: =MONTH(A21) -> 1 | J21: =IF(F21="net sales",E21, IF(F21="cogs",-E21, IF(OR(F21="marketing",F21="overhead",F21="payroll",F21="interest","amortization"),-E21,0))) -> -99.91
A22: 45294 | B22: net sales:product 1 | C22: 9.99 | D22: 37 | E22: 369.63 | F22: =IFERROR(LEFT(B22,FIND(":",B22)-1),B22) -> net sales | G22: =IFERROR(RIGHT(B22,LEN(B22)-FIND(":",B22)),"") -> product 1 | H22: =YEAR(A22) -> 2024 | I22: =MONTH(A22) -> 1 | J22: =IF(F22="net sales",E22, IF(F22="cogs",-E22, IF(OR(F22="marketing",F22="overhead",F22="payroll",F22="interest","amortization"),-E22,0))) -> 369.63
A23: 45294 | B23: net sales:product 2 | C23: 24.99 | D23: 9 | E23: 224.91 | F23: =IFERROR(LEFT(B23,FIND(":",B23)-1),B23) -> net sales | G23: =IFERROR(RIGHT(B23,LEN(B23)-FIND(":",B23)),"") -> product 2 | H23: =YEAR(A23) -> 2024 | I23: =MONTH(A23) -> 1 | J23: =IF(F23="net sales",E23, IF(F23="cogs",-E23, IF(OR(F23="marketing",F23="overhead",F23="payroll",F23="interest","amortization"),-E23,0))) -> 224.91
A24: 45294 | B24: net sales:product 3 | C24: 12.49 | D24: 222 | E24: 2772.78 | F24: =IFERROR(LEFT(B24,FIND(":",B24)-1),B24) -> net sales | G24: =IFERROR(RIGHT(B24,LEN(B24)-FIND(":",B24)),"") -> product 3 | H24: =YEAR(A24) -> 2024 | I24: =MONTH(A24) -> 1 | J24: =IF(F24="net sales",E24, IF(F24="cogs",-E24, IF(OR(F24="marketing",F24="overhead",F24="payroll",F24="interest","amortization"),-E24,0))) -> 2772.78
A25: 45295 | B25: cogs:product 1 | C25: 5.99 | D25: 39 | E25: 233.61 | F25: =IFERROR(LEFT(B25,FIND(":",B25)-1),B25) -> cogs | G25: =IFERROR(RIGHT(B25,LEN(B25)-FIND(":",B25)),"") -> product 1 | H25: =YEAR(A25) -> 2024 | I25: =MONTH(A25) -> 1 | J25: =IF(F25="net sales",E25, IF(F25="cogs",-E25, IF(OR(F25="marketing",F25="overhead",F25="payroll",F25="interest","amortization"),-E25,0))) -> -233.61
A26: 45295 | B26: cogs:product 2 | C26: 16.99 | D26: 2 | E26: 33.98 | F26: =IFERROR(LEFT(B26,FIND(":",B26)-1),B26) -> cogs | G26: =IFERROR(RIGHT(B26,LEN(B26)-FIND(":",B26)),"") -> product 2 | H26: =YEAR(A26) -> 2024 | I26: =MONTH(A26) -> 1 | J26: =IF(F26="net sales",E26, IF(F26="cogs",-E26, IF(OR(F26="marketing",F26="overhead",F26="payroll",F26="interest","amortization"),-E26,0))) -> -33.98
A27: 45295 | B27: cogs:product 3 | C27: 8.49 | D27: 180 | E27: 1528.2 | F27: =IFERROR(LEFT(B27,FIND(":",B27)-1),B27) -> cogs | G27: =IFERROR(RIGHT(B27,LEN(B27)-FIND(":",B27)),"") -> product 3 | H27: =YEAR(A27) -> 2024 | I27: =MONTH(A27) -> 1 | J27: =IF(F27="net sales",E27, IF(F27="cogs",-E27, IF(OR(F27="marketing",F27="overhead",F27="payroll",F27="interest","amortization"),-E27,0))) -> -1528.2
A28: 45295 | B28: marketing | C28: NA | D28: NA | E28: 99.98 | F28: =IFERROR(LEFT(B28,FIND(":",B28)-1),B28) -> marketing | G28: NA | H28: =YEAR(A28) -> 2024 | I28: =MONTH(A28) -> 1 | J28: =IF(F28="net sales",E28, IF(F28="cogs",-E28, IF(OR(F28="marketing",F28="overhead",F28="payroll",F28="interest","amortization"),-E28,0))) -> -99.98
A29: 45295 | B29: net sales:product 1 | C29: 9.99 | D29: 39 | E29: 389.61 | F29: =IFERROR(LEFT(B29,FIND(":",B29)-1),B29) -> net sales | G29: =IFERROR(RIGHT(B29,LEN(B29)-FIND(":",B29)),"") -> product 1 | H29: =YEAR(A29) -> 2024 | I29: =MONTH(A29) -> 1 | J29: =IF(F29="net sales",E29, IF(F29="cogs",-E29, IF(OR(F29="marketing",F29="overhead",F29="payroll",F29="interest","amortization"),-E29,0))) -> 389.61
A30: 45295 | B30: net sales:product 2 | C30: 24.99 | D30: 2 | E30: 49.98 | F30: =IFERROR(LEFT(B30,FIND(":",B30)-1),B30) -> net sales | G30: =IFERROR(RIGHT(B30,LEN(B30)-FIND(":",B30)),"") -> product 2 | H30: =YEAR(A30) -> 2024 | I30: =MONTH(A30) -> 1 | J30: =IF(F30="net sales",E30, IF(F30="cogs",-E30, IF(OR(F30="marketing",F30="overhead",F30="payroll",F30="interest","amortization"),-E30,0))) -> 49.98
A31: 45295 | B31: net sales:product 3 | C31: 12.49 | D31: 180 | E31: 2248.2 | F31: =IFERROR(LEFT(B31,FIND(":",B31)-1),B31) -> net sales | G31: =IFERROR(RIGHT(B31,LEN(B31)-FIND(":",B31)),"") -> product 3 | H31: =YEAR(A31) -> 2024 | I31: =MONTH(A31) -> 1 | J31: =IF(F31="net sales",E31, IF(F31="cogs",-E31, IF(OR(F31="marketing",F31="overhead",F31="payroll",F31="interest","amortization"),-E31,0))) -> 2248.2
A32: 45296 | B32: cogs:product 1 | C32: 5.99 | D32: 73 | E32: 437.27 | F32: =IFERROR(LEFT(B32,FIND(":",B32)-1),B32) -> cogs | G32: =IFERROR(RIGHT(B32,LEN(B32)-FIND(":",B32)),"") -> product 1 | H32: =YEAR(A32) -> 2024 | I32: =MONTH(A32) -> 1 | J32: =IF(F32="net sales",E32, IF(F32="cogs",-E32, IF(OR(F32="marketing",F32="overhead",F32="payroll",F32="interest","amortization"),-E32,0))) -> -437.27
A33: 45296 | B33: cogs:product 2 | C33: 16.99 | D33: 7 | E33: 118.93 | F33: =IFERROR(LEFT(B33,FIND(":",B33)-1),B33) -> cogs | G33: =IFERROR(RIGHT(B33,LEN(B33)-FIND(":",B33)),"") -> product 2 | H33: =YEAR(A33) -> 2024 | I33: =MONTH(A33) -> 1 | J33: =IF(F33="net sales",E33, IF(F33="cogs",-E33, IF(OR(F33="marketing",F33="overhead",F33="payroll",F33="interest","amortization"),-E33,0))) -> -118.93
A34: 45296 | B34: cogs:product 3 | C34: 8.49 | D34: 95 | E34: 806.55 | F34: =IFERROR(LEFT(B34,FIND(":",B34)-1),B34) -> cogs | G34: =IFERROR(RIGHT(B34,LEN(B34)-FIND(":",B34)),"") -> product 3 | H34: =YEAR(A34) -> 2024 | I34: =MONTH(A34) -> 1 | J34: =IF(F34="net sales",E34, IF(F34="cogs",-E34, IF(OR(F34="marketing",F34="overhead",F34="payroll",F34="interest","amortization"),-E34,0))) -> -806.55
A35: 45296 | B35: marketing | C35: NA | D35: NA | E35: 100.03 | F35: =IFERROR(LEFT(B35,FIND(":",B35)-1),B35) -> marketing | G35: NA | H35: =YEAR(A35) -> 2024 | I35: =MONTH(A35) -> 1 | J35: =IF(F35="net sales",E35, IF(F35="cogs",-E35, IF(OR(F35="marketing",F35="overhead",F35="payroll",F35="interest","amortization"),-E35,0))) -> -100.03
A36: 45296 | B36: net sales:product 1 | C36: 9.99 | D36: 73 | E36: 729.27 | F36: =IFERROR(LEFT(B36,FIND(":",B36)-1),B36) -> net sales | G36: =IFERROR(RIGHT(B36,LEN(B36)-FIND(":",B36)),"") -> product 1 | H36: =YEAR(A36) -> 2024 | I36: =MONTH(A36) -> 1 | J36: =IF(F36="net sales",E36, IF(F36="cogs",-E36, IF(OR(F36="marketing",F36="overhead",F36="payroll",F36="interest","amortization"),-E36,0))) -> 729.27
A37: 45296 | B37: net sales:product 2 | C37: 24.99 | D37: 7 | E37: 174.93 | F37: =IFERROR(LEFT(B37,FIND(":",B37)-1),B37) -> net sales | G37: =IFERROR(RIGHT(B37,LEN(B37)-FIND(":",B37)),"") -> product 2 | H37: =YEAR(A37) -> 2024 | I37: =MONTH(A37) -> 1 | J37: =IF(F37="net sales",E37, IF(F37="cogs",-E37, IF(OR(F37="marketing",F37="overhead",F37="payroll",F37="interest","amortization"),-E37,0))) -> 174.93
A38: 45296 | B38: net sales:product 3 | C38: 12.49 | D38: 95 | E38: 1186.55 | F38: =IFERROR(LEFT(B38,FIND(":",B38)-1),B38) -> net sales | G38: =IFERROR(RIGHT(B38,LEN(B38)-FIND(":",B38)),"") -> product 3 | H38: =YEAR(A38) -> 2024 | I38: =MONTH(A38) -> 1 | J38: =IF(F38="net sales",E38, IF(F38="cogs",-E38, IF(OR(F38="marketing",F38="overhead",F38="payroll",F38="interest","amortization"),-E38,0))) -> 1186.55
A39: 45296 | B39: payroll | C39: NA | D39: NA | E39: 1200 | F39: =IFERROR(LEFT(B39,FIND(":",B39)-1),B39) -> payroll | G39: NA | H39: =YEAR(A39) -> 2024 | I39: =MONTH(A39) -> 1 | J39: =IF(F39="net sales",E39, IF(F39="cogs",-E39, IF(OR(F39="marketing",F39="overhead",F39="payroll",F39="interest","amortization"),-E39,0))) -> -1200
A40: 45297 | B40: cogs:product 1 | C40: 5.99 | D40: 38 | E40: 227.62 | F40: =IFERROR(LEFT(B40,FIND(":",B40)-1),B40) -> cogs | G40: =IFERROR(RIGHT(B40,LEN(B40)-FIND(":",B40)),"") -> product 1 | H40: =YEAR(A40) -> 2024 | I40: =MONTH(A40) -> 1 | J40: =IF(F40="net sales",E40, IF(F40="cogs",-E40, IF(OR(F40="marketing",F40="overhead",F40="payroll",F40="interest","amortization"),-E40,0))) -> -227.62
...

Sheet P&L
A1: Ecommerce Company | M1: Calendar Year: | N1: 2024
A2: Profit & Loss Statement | B2: 1 | C2: 2 | D2: 3 | E2: 4 | F2: 5 | G2: 6 | H2: 7 | I2: 8 | J2: 9 | K2: 10 | L2: 11 | M2: 12
B3: Jan | C3: Feb | D3: Mar | E3: Apr | F3: May | G3: Jun | H3: Jul | I3: Aug | J3: Sep | K3: Oct | L3: Nov | M3: Dec | N3: Full Year
A4: REVENUE
A5: Net Sales | B5: =SUMIFS(Data!$E:$E, Data!$I:$I, $B$2, Data!$H:$H, $N$1, Data!$F:$F, "net sales") -> 67968.83 | C5: =SUMIFS(Data!$E:$E, Data!$I:$I, $C$2, Data!$H:$H, $N$1, Data!$F:$F, "net sales") -> 52966.62 | D5: =SUMIFS(Data!$E:$E, Data!$I:$I, $D$2, Data!$H:$H, $N$1, Data!$F:$F, "net sales") -> 55756.97 | E5: =SUMIFS(Data!$E:$E, Data!$I:$I, $E$2, Data!$H:$H, $N$1, Data!$F:$F, "net sales") -> 55429.22 | F5: =SUMIFS(Data!$E:$E, Data!$I:$I, $F$2, Data!$H:$H, $N$1, Data!$F:$F, "net sales") -> 57305.18 | G5: =SUMIFS(Data!$E:$E, Data!$I:$I, $G$2, Data!$H:$H, $N$1, Data!$F:$F, "net sales") -> 59788.56 | H5: =SUMIFS(Data!$E:$E, Data!$I:$I, $H$2, Data!$H:$H, $N$1, Data!$F:$F, "net sales") -> 58349.25 | I5: =SUMIFS(Data!$E:$E, Data!$I:$I, $I$2, Data!$H:$H, $N$1, Data!$F:$F, "net sales") -> 60709.84 | J5: =SUMIFS(Data!$E:$E, Data!$I:$I, $J$2, Data!$H:$H, $N$1, Data!$F:$F, "net sales") -> 65533.87 | K5: =SUMIFS(Data!$E:$E, Data!$I:$I, $K$2, Data!$H:$H, $N$1, Data!$F:$F, "net sales") -> 70224.86 | L5: =SUMIFS(Data!$E:$E, Data!$I:$I, $L$2, Data!$H:$H, $N$1, Data!$F:$F, "net sales") -> 48235.1 | M5: =SUMIFS(Data!$E:$E, Data!$I:$I, $M$2, Data!$H:$H, $N$1, Data!$F:$F, "net sales") -> 64497.17 | N5: =SUM(B5:M5) -> 716765.47
A6: COGS | B6: =SUMIFS(Data!$E:$E, Data!$I:$I, $B$2, Data!$H:$H, $N$1, Data!$F:$F, "cogs") -> 44936.83 | C6: =SUMIFS(Data!$E:$E, Data!$I:$I, $C$2, Data!$H:$H, $N$1, Data!$F:$F, "cogs") -> 35058.62 | D6: =SUMIFS(Data!$E:$E, Data!$I:$I, $D$2, Data!$H:$H, $N$1, Data!$F:$F, "cogs") -> 36936.97 | E6: =SUMIFS(Data!$E:$E, Data!$I:$I, $E$2, Data!$H:$H, $N$1, Data!$F:$F, "cogs") -> 36485.22 | F6: =SUMIFS(Data!$E:$E, Data!$I:$I, $F$2, Data!$H:$H, $N$1, Data!$F:$F, "cogs") -> 37745.18 | G6: =SUMIFS(Data!$E:$E, Data!$I:$I, $G$2, Data!$H:$H, $N$1, Data!$F:$F, "cogs") -> 39528.56 | H6: =SUMIFS(Data!$E:$E, Data!$I:$I, $H$2, Data!$H:$H, $N$1, Data!$F:$F, "cogs") -> 38461.25 | I6: =SUMIFS(Data!$E:$E, Data!$I:$I, $I$2, Data!$H:$H, $N$1, Data!$F:$F, "cogs") -> 40057.84 | J6: =SUMIFS(Data!$E:$E, Data!$I:$I, $J$2, Data!$H:$H, $N$1, Data!$F:$F, "cogs") -> 43521.87 | K6: =SUMIFS(Data!$E:$E, Data!$I:$I, $K$2, Data!$H:$H, $N$1, Data!$F:$F, "cogs") -> 46540.86 | L6: =SUMIFS(Data!$E:$E, Data!$I:$I, $L$2, Data!$H:$H, $N$1, Data!$F:$F, "cogs") -> 31699.1 | M6: =SUMIFS(Data!$E:$E, Data!$I:$I, $M$2, Data!$H:$H, $N$1, Data!$F:$F, "cogs") -> 42713.17 | N6: =SUM(B6:M6) -> 473685.47
A7: Gross Profit | B7: =B5-B6 -> 23032 | C7: =C5-C6 -> 17908 | D7: =D5-D6 -> 18820 | E7: =E5-E6 -> 18944 | F7: =F5-F6 -> 19560 | G7: =G5-G6 -> 20260 | H7: =H5-H6 -> 19888 | I7: =I5-I6 -> 20652 | ... M7: =M5-M6 -> 21784 | N7: =SUM(B7:M7) -> 243080
A8: Gross Margin | B8: =B7/B5 -> 0.33886121 | C8: =C7/C5 -> 0.33809973 | D8: =D7/D5 -> 0.33753628 | E8: =E7/E5 -> 0.3417692 | F8: =F7/F5 -> 0.3413304 | G8: =G7/G5 -> 0.33886081 | H8: =H7/H5 -> 0.34084414 | I8: =I7/I5 -> 0.3401755 | ... N8: =N7/N5 -> 0.33913464
A10: EXPENSES
A11: Payroll | B11: =SUMIFS(Data!$E:$E, Data!$I:$I, $B$2, Data!$H:$H, $N$1, Data!$F:$F, "payroll") -> 2400 | C11: =SUMIFS(Data!$E:$E, Data!$I:$I, $C$2, Data!$H:$H, $N$1, Data!$F:$F, "payroll") -> 2400 | D11: =SUMIFS(Data!$E:$E, Data!$I:$I, $D$2, Data!$H:$H, $N$1, Data!$F:$F, "payroll") -> 3600 | E11: =SUMIFS(Data!$E:$E, Data!$I:$I, $E$2, Data!$H:$H, $N$1, Data!$F:$F, "payroll") -> 2400 | F11: =SUMIFS(Data!$E:$E, Data!$I:$I, $F$2, Data!$H:$H, $N$1, Data!$F:$F, "payroll") -> 2400 | G11: =SUMIFS(Data!$E:$E, Data!$I:$I, $G$2, Data!$H:$H, $N$1, Data!$F:$F, "payroll") -> 2400 | H11: =SUMIFS(Data!$E:$E, Data!$I:$I, $H$2, Data!$H:$H, $N$1, Data!$F:$F, "payroll") -> 2400 | I11: =SUMIFS(Data!$E:$E, Data!$I:$I, $I$2, Data!$H:$H, $N$1, Data!$F:$F, "payroll") -> 3600 | J11: =SUMIFS(Data!$E:$E, Data!$I:$I, $J$2, Data!$H:$H, $N$1, Data!$F:$F, "payroll") -> 2400 | K11: =SUMIFS(Data!$E:$E, Data!$I:$I, $K$2, Data!$H:$H, $N$1, Data!$F:$F, "payroll") -> 2400 | L11: =SUMIFS(Data!$E:$E, Data!$I:$I, $L$2, Data!$H:$H, $N$1, Data!$F:$F, "payroll") -> 2400 | M11: =SUMIFS(Data!$E:$E, Data!$I:$I, $M$2, Data!$H:$H, $N$1, Data!$F:$F, "payroll") -> 2400 | N11: =SUM(B11:M11) -> 31200
A12: Overhead | B12: =SUMIFS(Data!$E:$E, Data!$I:$I, $B$2, Data!$H:$H, $N$1, Data!$F:$F, "overhead") -> 2324.25 | C12: =SUMIFS(Data!$E:$E, Data!$I:$I, $C$2, Data!$H:$H, $N$1, Data!$F:$F, "overhead") -> 2305.56 | D12: =SUMIFS(Data!$E:$E, Data!$I:$I, $D$2, Data!$H:$H, $N$1, Data!$F:$F, "overhead") -> 2303.53 | E12: =SUMIFS(Data!$E:$E, Data!$I:$I, $E$2, Data!$H:$H, $N$1, Data!$F:$F, "overhead") -> 2293.93 | F12: =SUMIFS(Data!$E:$E, Data!$I:$I, $F$2, Data!$H:$H, $N$1, Data!$F:$F, "overhead") -> 2315.6 | G12: =SUMIFS(Data!$E:$E, Data!$I:$I, $G$2, Data!$H:$H, $N$1, Data!$F:$F, "overhead") -> 2314.1 | H12: =SUMIFS(Data!$E:$E, Data!$I:$I, $H$2, Data!$H:$H, $N$1, Data!$F:$F, "overhead") -> 2314.57 | I12: =SUMIFS(Data!$E:$E, Data!$I:$I, $I$2, Data!$H:$H, $N$1, Data!$F:$F, "overhead") -> 2315.2 | J12: =SUMIFS(Data!$E:$E, Data!$I:$I, $J$2, Data!$H:$H, $N$1, Data!$F:$F, "overhead") -> 2320.04 | K12: =SUMIFS(Data!$E:$E, Data!$I:$I, $K$2, Data!$H:$H, $N$1, Data!$F:$F, "overhead") -> 2316.28 | L12: =SUMIFS(Data!$E:$E, Data!$I:$I, $L$2, Data!$H:$H, $N$1, Data!$F:$F, "overhead") -> 2312.51 | M12: =SUMIFS(Data!$E:$E, Data!$I:$I, $M$2, Data!$H:$H, $N$1, Data!$F:$F, "overhead") -> 2310.94 | N12: =SUM(B12:M12) -> 27746.51
A13: Marketing | B13: =SUMIFS(Data!$E:$E, Data!$I:$I, $B$2, Data!$H:$H, $N$1, Data!$F:$F, "marketing") -> 3099.34 | C13: =SUMIFS(Data!$E:$E, Data!$I:$I, $C$2, Data!$H:$H, $N$1, Data!$F:$F, "marketing") -> 2899.9 | D13: =SUMIFS(Data!$E:$E, Data!$I:$I, $D$2, Data!$H:$H, $N$1, Data!$F:$F, "marketing") -> 3099.96 | E13: =SUMIFS(Data!$E:$E, Data!$I:$I, $E$2, Data!$H:$H, $N$1, Data!$F:$F, "marketing") -> 2999.92 | F13: =SUMIFS(Data!$E:$E, Data!$I:$I, $F$2, Data!$H:$H, $N$1, Data!$F:$F, "marketing") -> 3099.71 | G13: =SUMIFS(Data!$E:$E, Data!$I:$I, $G$2, Data!$H:$H, $N$1, Data!$F:$F, "marketing") -> 3000.36 | H13: =SUMIFS(Data!$E:$E, Data!$I:$I, $H$2, Data!$H:$H, $N$1, Data!$F:$F, "marketing") -> 3099.39 | I13: =SUMIFS(Data!$E:$E, Data!$I:$I, $I$2, Data!$H:$H, $N$1, Data!$F:$F, "marketing") -> 3100.21 | J13: =SUMIFS(Data!$E:$E, Data!$I:$I, $J$2, Data!$H:$H, $N$1, Data!$F:$F, "marketing") -> 2999.9 | K13: =SUMIFS(Data!$E:$E, Data!$I:$I, $K$2, Data!$H:$H, $N$1, Data!$F:$F, "marketing") -> 3100.18 | L13: =SUMIFS(Data!$E:$E, Data!$I:$I, $L$2, Data!$H:$H, $N$1, Data!$F:$F, "marketing") -> 3000.26 | M13: =SUMIFS(Data!$E:$E, Data!$I:$I, $M$2, Data!$H:$H, $N$1, Data!$F:$F, "marketing") -> 3099.87 | N13: =SUM(B13:M13) -> 36599
A14: Depreciation | B14: 0 | C14: 0 | D14: 0 | E14: 0 | F14: 0 | G14: 0 | H14: 0 | I14: 0 | J14: 0 | K14: 0 | L14: 0 | M14: 0 | N14: 0
A15: Amortization | B15: =SUMIFS(Data!$E:$E, Data!$I:$I, $B$2, Data!$H:$H, $N$1, Data!$F:$F, "amortization") -> 50 | C15: =SUMIFS(Data!$E:$E, Data!$I:$I, $C$2, Data!$H:$H, $N$1, Data!$F:$F, "amortization") -> 50 | D15: =SUMIFS(Data!$E:$E, Data!$I:$I, $D$2, Data!$H:$H, $N$1, Data!$F:$F, "amortization") -> 50 | E15: =SUMIFS(Data!$E:$E, Data!$I:$I, $E$2, Data!$H:$H, $N$1, Data!$F:$F, "amortization") -> 50 | F15: =SUMIFS(Data!$E:$E, Data!$I:$I, $F$2, Data!$H:$H, $N$1, Data!$F:$F, "amortization") -> 50 | G15: =SUMIFS(Data!$E:$E, Data!$I:$I, $G$2, Data!$H:$H, $N$1, Data!$F:$F, "amortization") -> 50 | H15: =SUMIFS(Data!$E:$E, Data!$I:$I, $H$2, Data!$H:$H, $N$1, Data!$F:$F, "amortization") -> 50 | I15: =SUMIFS(Data!$E:$E, Data!$I:$I, $I$2, Data!$H:$H, $N$1, Data!$F:$F, "amortization") -> 50 | J15: =SUMIFS(Data!$E:$E, Data!$I:$I, $J$2, Data!$H:$H, $N$1, Data!$F:$F, "amortization") -> 50 | K15: =SUMIFS(Data!$E:$E, Data!$I:$I, $K$2, Data!$H:$H, $N$1, Data!$F:$F, "amortization") -> 50 | L15: =SUMIFS(Data!$E:$E, Data!$I:$I, $L$2, Data!$H:$H, $N$1, Data!$F:$F, "amortization") -> 50 | M15: =SUMIFS(Data!$E:$E, Data!$I:$I, $M$2, Data!$H:$H, $N$1, Data!$F:$F, "amortization") -> 50 | N15: =SUM(B15:M15) -> 600
A16: Interest | B16: =SUMIFS(Data!$E:$E, Data!$I:$I, $B$2, Data!$H:$H, $N$1, Data!$F:$F, "interest") -> 1297 | C16: =SUMIFS(Data!$E:$E, Data!$I:$I, $C$2, Data!$H:$H, $N$1, Data!$F:$F, "interest") -> 1242.56 | D16: =SUMIFS(Data!$E:$E, Data!$I:$I, $D$2, Data!$H:$H, $N$1, Data!$F:$F, "interest") -> 1214.12 | E16: =SUMIFS(Data!$E:$E, Data!$I:$I, $E$2, Data!$H:$H, $N$1, Data!$F:$F, "interest") -> 1290.64 | F16: =SUMIFS(Data!$E:$E, Data!$I:$I, $F$2, Data!$H:$H, $N$1, Data!$F:$F, "interest") -> 1262.4 | G16: =SUMIFS(Data!$E:$E, Data!$I:$I, $G$2, Data!$H:$H, $N$1, Data!$F:$F, "interest") -> 1286.44 | H16: =SUMIFS(Data!$E:$E, Data!$I:$I, $H$2, Data!$H:$H, $N$1, Data!$F:$F, "interest") -> 1258.28 | I16: =SUMIFS(Data!$E:$E, Data!$I:$I, $I$2, Data!$H:$H, $N$1, Data!$F:$F, "interest") -> 1282.24 | J16: =SUMIFS(Data!$E:$E, Data!$I:$I, $J$2, Data!$H:$H, $N$1, Data!$F:$F, "interest") -> 1280.16 | K16: =SUMIFS(Data!$E:$E, Data!$I:$I, $K$2, Data!$H:$H, $N$1, Data!$F:$F, "interest") -> 1252.12 | L16: =SUMIFS(Data!$E:$E, Data!$I:$I, $L$2, Data!$H:$H, $N$1, Data!$F:$F, "interest") -> 1250.04 | M16: =SUMIFS(Data!$E:$E, Data!$I:$I, $M$2, Data!$H:$H, $N$1, Data!$F:$F, "interest") -> 1247.92 | N16: =SUM(B16:M16) -> 15163.92
A17: Total Expenses | B17: =SUM(B11:B16) -> 9170.59 | C17: =SUM(C11:C16) -> 8898.02 | D17: =SUM(D11:D16) -> 10267.61 | E17: =SUM(E11:E16) -> 9034.49 | F17: =SUM(F11:F16) -> 9127.71 | G17: =SUM(G11:G16) -> 9050.9 | H17: =SUM(H11:H16) -> 9122.24 | I17: =SUM(I11:I16) -> 10347.65 | ... M17: =SUM(M11:M16) -> 9108.73 | N17: =SUM(B17:M17) -> 111309.43
A19: INCOME
A20: Earnings Before Tax | B20: =B7-B17 -> 13861.41 | C20: =C7-C17 -> 9009.98 | D20: =D7-D17 -> 8552.39 | E20: =E7-E17 -> 9909.51 | F20: =F7-F17 -> 10432.29 | G20: =G7-G17 -> 11209.1 | H20: =H7-H17 -> 10765.76 | I20: =I7-I17 -> 10304.35 | ... N20: =N7-N17 -> 131770.57
A21: Taxes | B21: =B20*0.21 -> 2910.8961 | C21: =C20*0.21 -> 1892.0958 | D21: =D20*0.21 -> 1796.0019 | E21: =E20*0.21 -> 2080.9971 | F21: =F20*0.21 -> 2190.7809 | G21: =G20*0.21 -> 2353.911 | H21: =H20*0.21 -> 2260.8096 | I21: =I20*0.21 -> 2163.9135 | ... N21: =N20*0.21 -> 27671.82
A22: Net Earnings | B22: =B20-B21 -> 10950.514 | C22: =C20-C21 -> 7117.8842 | D22: =D20-D21 -> 6756.3881 | E22: =E20-E21 -> 7828.5129 | F22: =F20-F21 -> 8241.5091 | G22: =G20-G21 -> 8855.189 | H22: =H20-H21 -> 8504.9504 | I22: =I20-I21 -> 8140.4365 | ... N22: =N20-N21 -> 104098.75
A23: EBIT | B23: =B22+B16+B21 -> 15158.41 | C23: =C22+C16+C21 -> 10252.54 | D23: =D22+D16+D21 -> 9766.51 | E23: =E22+E16+E21 -> 11200.15 | F23: =F22+F16+F21 -> 11694.69 | G23: =G22+G16+G21 -> 12495.54 | H23: =H22+H16+H21 -> 12024.04 | I23: =I22+I16+I21 -> 11586.59 | ... N23: =N22+N16+N21 -> 146934.49
A24: EBITDA | B24: =B22+B16+B21+B14+B15 -> 15208.41 | C24: =C22+C16+C21+C14+C15 -> 10302.54 | D24: =D22+D16+D21+D14+D15 -> 9816.51 | E24: =E22+E16+E21+E14+E15 -> 11250.15 | F24: =F22+F16+F21+F14+F15 -> 11744.69 | G24: =G22+G16+G21+G14+G15 -> 12545.54 | H24: =H22+H16+H21+H14+H15 -> 12074.04 | I24: =I22+I16+I21+I14+I15 -> 11636.59 | ... N24: =N22+N16+N21+N14+N15 -> 147534.49

Sheet Products
A1: Row Labels | B1: Sum of quantity | G1: Average Daily Profit
A2: 2024 | B2: 117906 | H2: AVG 2024 | I2: AVG 2025
A3: product 1 | B3: 33816 | G3: Product 1 | H3: =AVERAGEIFS(Data!$J:$J, Data!$G:$G, "product 1", Data!$H:$H, 2024) -> 362.92725 | I3: =AVERAGEIFS(Data!$J:$J, Data!$G:$G, "product 1", Data!$H:$H, 2025) -> 422.95264
A4: product 2 | B4: 3634 | G4: Product 2 | H4: =AVERAGEIFS(Data!$J:$J, Data!$G:$G, "product 2", Data!$H:$H, 2024) -> 63.48918 | I4: =AVERAGEIFS(Data!$J:$J, Data!$G:$G, "product 2", Data!$H:$H, 2025) -> 83.365945
A5: product 3 | B5: 80456 | G5: Product 3 | H5: =AVERAGEIFS(Data!$J:$J, Data!$G:$G, "product 3", Data!$H:$H, 2024) -> 62.904454 | I5: =AVERAGEIFS(Data!$J:$J, Data!$G:$G, "product 3", Data!$H:$H, 2025) -> 38.914192
A6: 2025 | B6: 129514
A7: product 1 | B7: 37844
A8: product 2 | B8: 2798
A9: product 3 | B9: 88872
A10: Grand Total | B10: 247420
A12: Growth
B13: Units 2024 | C13: Units 2025 | D13: Growth | E13: Growth %
A14: Product 1 | B14: =GETPIVOTDATA("quantity",$A$1,"product","product 1","year",2024) -> 33816 | C14: =GETPIVOTDATA("quantity",$A$1,"product","product 1","year",2025) -> 37844 | D14: =C14-B14 -> 4028 | E14: =D14/B14 -> 0.11911521
A15: Product 2 | B15: =GETPIVOTDATA("quantity",$A$1,"product","product 2","year",2024) -> 3634 | C15: =GETPIVOTDATA("quantity",$A$1,"product","product 2","year",2025) -> 2798 | D15: =C15-B15 -> -836 | E15: =D15/B15 -> -0.23004953
A16: Product 3 | B16: =GETPIVOTDATA("quantity",$A$1,"product","product 3","year",2024) -> 80456 | C16: =GETPIVOTDATA("quantity",$A$1,"product","product 3","year",2025) -> 88872 | D16: =C16-B16 -> 8416 | E16: =D16/B16 -> 0.10460376
A17: All Products | B17: =GETPIVOTDATA("quantity",$A$1,"year",2024) -> 117906 | C17: =GETPIVOTDATA("quantity",$A$1,"year",2025) -> 129514 | D17: =C17-B17 -> 11608 | E17: =D17/B17 -> 0.098451309
A19: year | B19: product | C19: Max of quantity
A20: 2024 | C20: 249
B21: product 1 | C21: 99
B22: product 2 | C22: 10
B23: product 3 | C23: 249
A24: 2025 | C24: 273
B25: product 1 | C25: 103
B26: product 2 | C26: 9
B27: product 3 | C27: 273
A28: Grand Total | C28: 273
A30: Max Units Per Day
B31: Max 2024 | C31: Max 2025 | D31: Difference
A32: Product 1 | B32: =GETPIVOTDATA("quantity",$A$19,"product","product 1","year",2024) -> 99 | C32: =GETPIVOTDATA("quantity",$A$19,"product","product 1","year",2025) -> 103 | D32: =C32-B32 -> 4
A33: Product 2 | B33: =GETPIVOTDATA("quantity",$A$19,"product","product 2","year",2024) -> 10 | C33: =GETPIVOTDATA("quantity",$A$19,"product","product 2","year",2025) -> 9 | D33: =C33-B33 -> -1
A34: Product 3 | B34: =GETPIVOTDATA("quantity",$A$19,"product","product 3","year",2024) -> 249 | C34: =GETPIVOTDATA("quantity",$A$19,"product","product 3","year",2025) -> 273 | D34: =C34-B34 -> 24

Sheet Charts

Sheet Analysis
A1: category | B1: net sales
A3: Sum of total | B3: Column Labels
A4: Row Labels | B4: 2024 | C4: 2025 | D4: Grand Total
A5: 1 | B5: 67968.83 | C5: 63068.1 | D5: 131036.93
A6: 2 | B6: 52966.62 | C6: 50910.72 | D6: 103877.34
A7: 3 | B7: 55756.97 | C7: 63397.1 | D7: 119154.07
A8: 4 | B8: 55429.22 | C8: 65832.4 | D8: 121261.62
A9: 5 | B9: 57305.18 | C9: 64291.96 | D9: 121597.14
A10: 6 | B10: 59788.56 | C10: 56920.56 | D10: 116709.12
A11: 7 | B11: 58349.25 | C11: 73444.38 | D11: 131793.63
A12: 8 | B12: 60709.84 | C12: 62057.77 | D12: 122767.61
A13: 9 | B13: 65533.87 | C13: 66704.1 | D13: 132237.97
A14: 10 | B14: 70224.86 | C14: 72541.66 | D14: 142766.52
A15: 11 | B15: 48235.1 | C15: 73094.14 | D15: 121329.24
A16: 12 | B16: 64497.17 | C16: 66734.54 | D16: 131231.71
A17: Grand Total | B17: 716765.47 | C17: 778997.43 | D17: 1495762.9

Sheet More Analysis
A1: Sum of quantity | B1: Column Labels
A2: Row Labels | B2: 2024 | C2: 2025 | D2: Grand Total
A3: 1 | B3: 11234 | C3: 10380 | D3: 21614
A4: 2 | B4: 8676 | C4: 8356 | D4: 17032
A5: 3 | B5: 9106 | C5: 10580 | D5: 19686
A6: 4 | B6: 9156 | C6: 11020 | D6: 20176
A7: 5 | B7: 9464 | C7: 10608 | D7: 20072
A8: 6 | B8: 9788 | C8: 9388 | D8: 19176
A9: 7 | B9: 9650 | C9: 12124 | D9: 21774
A10: 8 | B10: 10032 | C10: 10446 | D10: 20478
A11: 9 | B11: 10726 | C11: 11180 | D11: 21906
A12: 10 | B12: 11528 | C12: 12168 | D12: 23696
A13: 11 | B13: 7980 | C13: 12172 | D13: 20152
A14: 12 | B14: 10566 | C14: 11092 | D14: 21658
A15: Grand Total | B15: 117906 | C15: 129514 | D15: 247420
A17: Sum of quantity | B17: Column Labels
A18: Row Labels | B18: 2024 | C18: 2025 | D18: Grand Total
A19: product 1 | B19: 33816 | C19: 37844 | D19: 71660
A20: product 2 | B20: 3634 | C20: 2798 | D20: 6432
A21: product 3 | B21: 80456 | C21: 88872 | D21: 169328
A22: Grand Total | B22: 117906 | C22: 129514 | D22: 247420
